Workbook

Sheet Cover Page
B2: Report Title
B3: Report Number
B4: Revision
B5: Report Comments
B7: Name, address, location of performance of the laboratory activities | C7: Centre for Oil and Gas Research and Development 144 Dysart Road, Winnipeg, Manitoba, R3T 2N2, (204) 474-7001
B9: ISSUED TO:
B10: Name
B11: Company/Institution
B12: Address
B13: Phone #
B15: Test Method (number, name)
B17: Testing dates
D21: Name/Title | H21: Signature/Date
B23: Prepared
B25: Reviewed
B27: Authorized
B30: [This report shall not be reproduced except in full without the written authority of COGRAD Laboratory]
B31: [The results issued within this report relate only to the samples that were submitted and tested as received]

Sheet Results-PAHs
A1: ='Cover Page'!B2 -> Report Title | B1: ='Cover Page'!C2 -> 0
A2: ='Cover Page'!B3 -> Report Number | B2: ='Cover Page'!C3 -> 0
A3: ='Cover Page'!B4 -> Revision | B3: ='Cover Page'!C4 -> 0
A6: Analyte | B6: Limit of Detection (add units)* | C6: Sample Concentration (add units) | M6: =C6 -> Sample Concentration (add units) | X6: =C6 -> Sample Concentration (add units) | AI6: =C6 -> Sample Concentration (add units) | AT6: =C6 -> Sample Concentration (add units) | BE6: =C6 -> Sample Concentration (add units) | BP6: =C6 -> Sample Concentration (add units) | CA6: =C6 -> Sample Concentration (add units) | CL6: =C6 -> Sample Concentration (add units) | CY6: =C6 -> Sample Concentration (add units) | DL6: =C6 -> Sample Concentration (add units) | DY6: =C6 -> Sample Concentration (add units) | EL6: =C6 -> Sample Concentration (add units)
C7: ='Sample Set Info'!B32 -> 0 | D7: ='Sample Set Info'!B33 -> 0 | E7: ='Sample Set Info'!B34 -> 0 | F7: ='Sample Set Info'!B35 -> 0 | G7: ='Sample Set Info'!B36 -> 0 | H7: ='Sample Set Info'!B37 -> 0 | I7: ='Sample Set Info'!B38 -> 0 | J7: ='Sample Set Info'!B39 -> 0 | K7: ='Sample Set Info'!B40 -> 0 | L7: ='Sample Set Info'!B41 -> 0 | M7: ='Sample Set Info'!B42 -> 0 | N7: ='Sample Set Info'!B43 -> 0 | O7: ='Sample Set Info'!B44 -> 0 | P7: ='Sample Set Info'!B45 -> 0 | Q7: ='Sample Set Info'!B46 -> 0 | R7: ='Sample Set Info'!B47 -> 0 | S7: ='Sample Set Info'!B48 -> 0 | T7: ='Sample Set Info'!B49 -> 0 | U7: ='Sample Set Info'!B50 -> 0 | V7: ='Sample Set Info'!B51 -> 0 | W7: ='Sample Set Info'!B52 -> 0 | X7: ='Sample Set Info'!B53 -> 0 | Y7: ='Sample Set Info'!B54 -> 0 | Z7: ='Sample Set Info'!B55 -> 0 | AA7: ='Sample Set Info'!B56 -> 0 | AB7: ='Sample Set Info'!B57 -> 0 | AC7: ='Sample Set Info'!B58 -> 0 | AD7: ='Sample Set Info'!B59 -> 0 | AE7: ='Sample Set Info'!B60 -> 0 | AF7: ='Sample Set Info'!B61 -> 0 | AG7: ='Sample Set Info'!B62 -> 0 | AH7: ='Sample Set Info'!B63 -> 0 | AI7: ='Sample Set Info'!B64 -> 0 | AJ7: ='Sample Set Info'!B65 -> 0 | AK7: ='Sample Set Info'!B66 -> 0 | AL7: ='Sample Set Info'!B67 -> 0 | AM7: ='Sample Set Info'!B68 -> 0 | AN7: ='Sample Set Info'!B69 -> 0 | AO7: ='Sample Set Info'!B70 -> 0 | AP7: ='Sample Set Info'!B71 -> 0 | AQ7: ='Sample Set Info'!B72 -> 0 | AR7: ='Sample Set Info'!B73 -> 0 | AS7: ='Sample Set Info'!B74 -> 0 | AT7: ='Sample Set Info'!B75 -> 0 | AU7: ='Sample Set Info'!B76 -> 0 | AV7: ='Sample Set Info'!B77 -> 0 | AW7: ='Sample Set Info'!B78 -> 0 | AX7: ='Sample Set Info'!B79 -> 0 | AY7: ='Sample Set Info'!B80 -> 0 | AZ7: ='Sample Set Info'!B81 -> 0 | BA7: ='Sample Set Info'!B82 -> 0 | BB7: ='Sample Set Info'!B83 -> 0 | BC7: ='Sample Set Info'!B84 -> 0 | BD7: ='Sample Set Info'!B85 -> 0 | BE7: ='Sample Set Info'!B86 -> 0 | BF7: ='Sample Set Info'!B87 -> 0 | BG7: ='Sample Set Info'!B88 -> 0 | BH7: ='Sample Set Info'!B89 -> 0 | BI7: ='Sample Set Info'!B90 -> 0 | BJ7: ='Sample Set Info'!B91 -> 0 | BK7: ='Sample Set Info'!B92 -> 0 | BL7: ='Sample Set Info'!B93 -> 0 | BM7: ='Sample Set Info'!B94 -> 0 | BN7: ='Sample Set Info'!B95 -> 0 | BO7: ='Sample Set Info'!B96 -> 0 | BP7: ='Sample Set Info'!B97 -> 0 | BQ7: ='Sample Set Info'!B98 -> 0 | BR7: ='Sample Set Info'!B99 -> 0 | BS7: ='Sample Set Info'!B100 -> 0 | BT7: ='Sample Set Info'!B101 -> 0 | BU7: ='Sample Set Info'!B102 -> 0 | BV7: ='Sample Set Info'!B103 -> 0 | BW7: ='Sample Set Info'!B104 -> 0 | BX7: ='Sample Set Info'!B105 -> 0 | BY7: ='Sample Set Info'!B106 -> 0 | BZ7: ='Sample Set Info'!B107 -> 0 | CA7: ='Sample Set Info'!B108 -> 0 | CB7: ='Sample Set Info'!B109 -> 0 | CC7: ='Sample Set Info'!B110 -> 0 | CD7: ='Sample Set Info'!B111 -> 0 | CE7: ='Sample Set Info'!B112 -> 0 | CF7: ='Sample Set Info'!B113 -> 0 | CG7: ='Sample Set Info'!B114 -> 0 | CH7: ='Sample Set Info'!B115 -> 0 | CI7: ='Sample Set Info'!B116 -> 0 | CJ7: ='Sample Set Info'!B117 -> 0 | CK7: ='Sample Set Info'!B118 -> 0 | CL7: ='Sample Set Info'!B119 -> 0 | CM7: ='Sample Set Info'!B120 -> 0 | CN7: ='Sample Set Info'!B121 -> 0 | CO7: ='Sample Set Info'!B122 -> 0 | CP7: ='Sample Set Info'!B123 -> 0 | CQ7: ='Sample Set Info'!B124 -> 0 | CR7: ='Sample Set Info'!B125 -> 0 | CS7: ='Sample Set Info'!B126 -> 0 | CT7: ='Sample Set Info'!B127 -> 0 | CU7: ='Sample Set Info'!B128 -> 0 | CV7: ='Sample Set Info'!B129 -> 0 | CW7: ='Sample Set Info'!B130 -> 0 | CX7: ='Sample Set Info'!B131 -> 0 | CY7: ='Sample Set Info'!B132 -> 0 | CZ7: ='Sample Set Info'!B133 -> 0 | DA7: ='Sample Set Info'!B134 -> 0 | DB7: ='Sample Set Info'!B135 -> 0 | DC7: ='Sample Set Info'!B136 -> 0 | DD7: ='Sample Set Info'!B137 -> 0 | DE7: ='Sample Set Info'!B138 -> 0 | DF7: ='Sample Set Info'!B139 -> 0 | DG7: ='Sample Set Info'!B140 -> 0 | DH7: ='Sample Set Info'!B141 -> 0 | DI7: ='Sample Set Info'!B142 -> 0 | DJ7: ='Sample Set Info'!B143 -> 0 | DK7: ='Sample Set Info'!B144 -> 0 | DL7: ='Sample Set Info'!B145 -> 0 | DM7: ='Sample Set Info'!B146 -> 0 | DN7: ='Sample Set Info'!B147 -> 0 | DO7: ='Sample Set Info'!B148 -> 0 | DP7: ='Sample Set Info'!B149 -> 0 | DQ7: ='Sample Set Info'!B150 -> 0 | DR7: ='Sample Set Info'!B151 -> 0 | DS7: ='Sample Set Info'!B152 -> 0 | DT7: ='Sample Set Info'!B153 -> 0 | DU7: ='Sample Set Info'!B154 -> 0 | DV7: ='Sample Set Info'!B155 -> 0 | DW7: ='Sample Set Info'!B156 -> 0 | DX7: ='Sample Set Info'!B157 -> 0 | DY7: ='Sample Set Info'!B158 -> 0 | DZ7: ='Sample Set Info'!B159 -> 0 | EA7: ='Sample Set Info'!B160 -> 0 | EB7: ='Sample Set Info'!B161 -> 0 | EC7: ='Sample Set Info'!B162 -> 0 | ED7: ='Sample Set Info'!B163 -> 0 | EE7: ='Sample Set Info'!B164 -> 0 | EF7: ='Sample Set Info'!B165 -> 0 | EG7: ='Sample Set Info'!B166 -> 0 | EH7: ='Sample Set Info'!B167 -> 0 | EI7: ='Sample Set Info'!B168 -> 0 | EJ7: ='Sample Set Info'!B169 -> 0 | EK7: ='Sample Set Info'!B170 -> 0 | EL7: ='Sample Set Info'!B171 -> 0 | EM7: ='Sample Set Info'!B172 -> 0 | EN7: ='Sample Set Info'!B173 -> 0 | EO7: ='Sample Set Info'!B174 -> 0 | EP7: ='Sample Set Info'!B175 -> 0 | EQ7: ='Sample Set Info'!B176 -> 0 | ER7: ='Sample Set Info'!B177 -> 0 | ES7: ='Sample Set Info'!B178 -> 0 | ET7: ='Sample Set Info'!B179 -> 0 | EU7: ='Sample Set Info'!B180 -> 0 | EV7: ='Sample Set Info'!B181 -> 0
A8: ='Analyte List'!A9 -> Napthalene | B8: ='Analyte List'!K9 -> 0 | C8: ='Sample Conc Calc'!AF433 -> #DIV/0! | D8: ='Sample Conc Calc'!AG433 -> #DIV/0! | E8: ='Sample Conc Calc'!AH433 -> #DIV/0! | F8: ='Sample Conc Calc'!AI433 -> #DIV/0! | G8: ='Sample Conc Calc'!AJ433 -> #DIV/0! | H8: ='Sample Conc Calc'!AK433 -> #DIV/0! | I8: ='Sample Conc Calc'!AL433 -> #DIV/0! | J8: ='Sample Conc Calc'!AM433 -> #DIV/0! | ... EV8: ='Sample Conc Calc'!FY433 -> #DIV/0!
A9: ='Analyte List'!A10 -> Acenapthylene | B9: ='Analyte List'!K10 -> 0 | C9: ='Sample Conc Calc'!AF434 -> #DIV/0! | D9: ='Sample Conc Calc'!AG434 -> #DIV/0! | E9: ='Sample Conc Calc'!AH434 -> #DIV/0! | F9: ='Sample Conc Calc'!AI434 -> #DIV/0! | G9: ='Sample Conc Calc'!AJ434 -> #DIV/0! | H9: ='Sample Conc Calc'!AK434 -> #DIV/0! | I9: ='Sample Conc Calc'!AL434 -> #DIV/0! | J9: ='Sample Conc Calc'!AM434 -> #DIV/0! | ... EV9: ='Sample Conc Calc'!FY434 -> #DIV/0!
A10: ='Analyte List'!A11 -> Acenaphthene | B10: ='Analyte List'!K11 -> 0 | C10: ='Sample Conc Calc'!AF435 -> #DIV/0! | D10: ='Sample Conc Calc'!AG435 -> #DIV/0! | E10: ='Sample Conc Calc'!AH435 -> #DIV/0! | F10: ='Sample Conc Calc'!AI435 -> #DIV/0! | G10: ='Sample Conc Calc'!AJ435 -> #DIV/0! | H10: ='Sample Conc Calc'!AK435 -> #DIV/0! | I10: ='Sample Conc Calc'!AL435 -> #DIV/0! | J10: ='Sample Conc Calc'!AM435 -> #DIV/0! | ... EV10: ='Sample Conc Calc'!FY435 -> #DIV/0!
A11: ='Analyte List'!A12 -> Fluorene | B11: ='Analyte List'!K12 -> 0 | C11: ='Sample Conc Calc'!AF436 -> #DIV/0! | D11: ='Sample Conc Calc'!AG436 -> #DIV/0! | E11: ='Sample Conc Calc'!AH436 -> #DIV/0! | F11: ='Sample Conc Calc'!AI436 -> #DIV/0! | G11: ='Sample Conc Calc'!AJ436 -> #DIV/0! | H11: ='Sample Conc Calc'!AK436 -> #DIV/0! | I11: ='Sample Conc Calc'!AL436 -> #DIV/0! | J11: ='Sample Conc Calc'!AM436 -> #DIV/0! | ... EV11: ='Sample Conc Calc'!FY436 -> #DIV/0!
A12: ='Analyte List'!A13 -> Phenanthrene | B12: ='Analyte List'!K13 -> 0 | C12: ='Sample Conc Calc'!AF437 -> #DIV/0! | D12: ='Sample Conc Calc'!AG437 -> #DIV/0! | E12: ='Sample Conc Calc'!AH437 -> #DIV/0! | F12: ='Sample Conc Calc'!AI437 -> #DIV/0! | G12: ='Sample Conc Calc'!AJ437 -> #DIV/0! | H12: ='Sample Conc Calc'!AK437 -> #DIV/0! | I12: ='Sample Conc Calc'!AL437 -> #DIV/0! | J12: ='Sample Conc Calc'!AM437 -> #DIV/0! | ... EV12: ='Sample Conc Calc'!FY437 -> #DIV/0!
A13: ='Analyte List'!A14 -> Anthracene | B13: ='Analyte List'!K14 -> 0 | C13: ='Sample Conc Calc'!AF438 -> #DIV/0! | D13: ='Sample Conc Calc'!AG438 -> #DIV/0! | E13: ='Sample Conc Calc'!AH438 -> #DIV/0! | F13: ='Sample Conc Calc'!AI438 -> #DIV/0! | G13: ='Sample Conc Calc'!AJ438 -> #DIV/0! | H13: ='Sample Conc Calc'!AK438 -> #DIV/0! | I13: ='Sample Conc Calc'!AL438 -> #DIV/0! | J13: ='Sample Conc Calc'!AM438 -> #DIV/0! | ... EV13: ='Sample Conc Calc'!FY438 -> #DIV/0!
A14: ='Analyte List'!A15 -> Fluoranthene | B14: ='Analyte List'!K15 -> 0 | C14: ='Sample Conc Calc'!AF439 -> #DIV/0! | D14: ='Sample Conc Calc'!AG439 -> #DIV/0! | E14: ='Sample Conc Calc'!AH439 -> #DIV/0! | F14: ='Sample Conc Calc'!AI439 -> #DIV/0! | G14: ='Sample Conc Calc'!AJ439 -> #DIV/0! | H14: ='Sample Conc Calc'!AK439 -> #DIV/0! | I14: ='Sample Conc Calc'!AL439 -> #DIV/0! | J14: ='Sample Conc Calc'!AM439 -> #DIV/0! | ... EV14: ='Sample Conc Calc'!FY439 -> #DIV/0!
A15: ='Analyte List'!A16 -> Pyrene | B15: ='Analyte List'!K16 -> 0 | C15: ='Sample Conc Calc'!AF440 -> #DIV/0! | D15: ='Sample Conc Calc'!AG440 -> #DIV/0! | E15: ='Sample Conc Calc'!AH440 -> #DIV/0! | F15: ='Sample Conc Calc'!AI440 -> #DIV/0! | G15: ='Sample Conc Calc'!AJ440 -> #DIV/0! | H15: ='Sample Conc Calc'!AK440 -> #DIV/0! | I15: ='Sample Conc Calc'!AL440 -> #DIV/0! | J15: ='Sample Conc Calc'!AM440 -> #DIV/0! | ... EV15: ='Sample Conc Calc'!FY440 -> #DIV/0!
A16: ='Analyte List'!A17 -> Benz(a)anthracene | B16: ='Analyte List'!K17 -> 0 | C16: ='Sample Conc Calc'!AF441 -> #DIV/0! | D16: ='Sample Conc Calc'!AG441 -> #DIV/0! | E16: ='Sample Conc Calc'!AH441 -> #DIV/0! | F16: ='Sample Conc Calc'!AI441 -> #DIV/0! | G16: ='Sample Conc Calc'!AJ441 -> #DIV/0! | H16: ='Sample Conc Calc'!AK441 -> #DIV/0! | I16: ='Sample Conc Calc'!AL441 -> #DIV/0! | J16: ='Sample Conc Calc'!AM441 -> #DIV/0! | ... EV16: ='Sample Conc Calc'!FY441 -> #DIV/0!
A17: ='Analyte List'!A18 -> Chrysene | B17: ='Analyte List'!K18 -> 0 | C17: ='Sample Conc Calc'!AF442 -> #DIV/0! | D17: ='Sample Conc Calc'!AG442 -> #DIV/0! | E17: ='Sample Conc Calc'!AH442 -> #DIV/0! | F17: ='Sample Conc Calc'!AI442 -> #DIV/0! | G17: ='Sample Conc Calc'!AJ442 -> #DIV/0! | H17: ='Sample Conc Calc'!AK442 -> #DIV/0! | I17: ='Sample Conc Calc'!AL442 -> #DIV/0! | J17: ='Sample Conc Calc'!AM442 -> #DIV/0! | ... EV17: ='Sample Conc Calc'!FY442 -> #DIV/0!
A18: ='Analyte List'!A19 -> Benzo(b)fluoranthracene | B18: ='Analyte List'!K19 -> 0 | C18: ='Sample Conc Calc'!AF443 -> #DIV/0! | D18: ='Sample Conc Calc'!AG443 -> #DIV/0! | E18: ='Sample Conc Calc'!AH443 -> #DIV/0! | F18: ='Sample Conc Calc'!AI443 -> #DIV/0! | G18: ='Sample Conc Calc'!AJ443 -> #DIV/0! | H18: ='Sample Conc Calc'!AK443 -> #DIV/0! | I18: ='Sample Conc Calc'!AL443 -> #DIV/0! | J18: ='Sample Conc Calc'!AM443 -> #DIV/0! | ... EV18: ='Sample Conc Calc'!FY443 -> #DIV/0!
A19: ='Analyte List'!A20 -> Benzo(k)fluoranthracene | B19: ='Analyte List'!K20 -> 0 | C19: ='Sample Conc Calc'!AF444 -> #DIV/0! | D19: ='Sample Conc Calc'!AG444 -> #DIV/0! | E19: ='Sample Conc Calc'!AH444 -> #DIV/0! | F19: ='Sample Conc Calc'!AI444 -> #DIV/0! | G19: ='Sample Conc Calc'!AJ444 -> #DIV/0! | H19: ='Sample Conc Calc'!AK444 -> #DIV/0! | I19: ='Sample Conc Calc'!AL444 -> #DIV/0! | J19: ='Sample Conc Calc'!AM444 -> #DIV/0! | ... EV19: ='Sample Conc Calc'!FY444 -> #DIV/0!
... A23: ='Analyte List'!A24 -> Benzo(g,h,i)perylene | B23: ='Analyte List'!K24 -> 0 | C23: ='Sample Conc Calc'!AF448 -> #DIV/0! | D23: ='Sample Conc Calc'!AG448 -> #DIV/0! | E23: ='Sample Conc Calc'!AH448 -> #DIV/0! | F23: ='Sample Conc Calc'!AI448 -> #DIV/0! | G23: ='Sample Conc Calc'!AJ448 -> #DIV/0! | H23: ='Sample Conc Calc'!AK448 -> #DIV/0! | I23: ='Sample Conc Calc'!AL448 -> #DIV/0! | J23: ='Sample Conc Calc'!AM448 -> #DIV/0! | ... EV23: ='Sample Conc Calc'!FY448 -> #DIV/0!

Sheet Results-APAHs
A1: ='Cover Page'!B2 -> Report Title
A2: ='Cover Page'!B3 -> Report Number
A3: ='Cover Page'!B4 -> Revision
A6: Analyte | B6: Limit of Detection (add units)* | C6: Sample Concentration (add units) | M6: =C6 -> Sample Concentration (add units) | X6: =C6 -> Sample Concentration (add units) | AI6: =C6 -> Sample Concentration (add units) | AT6: =C6 -> Sample Concentration (add units) | BE6: =C6 -> Sample Concentration (add units) | BP6: =C6 -> Sample Concentration (add units) | CA6: =C6 -> Sample Concentration (add units) | CL6: =C6 -> Sample Concentration (add units) | CY6: =C6 -> Sample Concentration (add units) | DL6: =C6 -> Sample Concentration (add units) | DY6: =C6 -> Sample Concentration (add units) | EL6: =C6 -> Sample Concentration (add units)
C7: ='Sample Set Info'!B32 -> 0 | D7: ='Sample Set Info'!B33 -> 0 | E7: ='Sample Set Info'!B34 -> 0 | F7: ='Sample Set Info'!B35 -> 0 | G7: ='Sample Set Info'!B36 -> 0 | H7: ='Sample Set Info'!B37 -> 0 | I7: ='Sample Set Info'!B38 -> 0 | J7: ='Sample Set Info'!B39 -> 0 | K7: ='Sample Set Info'!B40 -> 0 | L7: ='Sample Set Info'!B41 -> 0 | M7: ='Sample Set Info'!B42 -> 0 | N7: ='Sample Set Info'!B43 -> 0 | O7: ='Sample Set Info'!B44 -> 0 | P7: ='Sample Set Info'!B45 -> 0 | Q7: ='Sample Set Info'!B46 -> 0 | R7: ='Sample Set Info'!B47 -> 0 | S7: ='Sample Set Info'!B48 -> 0 | T7: ='Sample Set Info'!B49 -> 0 | U7: ='Sample Set Info'!B50 -> 0 | V7: ='Sample Set Info'!B51 -> 0 | W7: ='Sample Set Info'!B52 -> 0 | X7: ='Sample Set Info'!B53 -> 0 | Y7: ='Sample Set Info'!B54 -> 0 | Z7: ='Sample Set Info'!B55 -> 0 | AA7: ='Sample Set Info'!B56 -> 0 | AB7: ='Sample Set Info'!B57 -> 0 | AC7: ='Sample Set Info'!B58 -> 0 | AD7: ='Sample Set Info'!B59 -> 0 | AE7: ='Sample Set Info'!B60 -> 0 | AF7: ='Sample Set Info'!B61 -> 0 | AG7: ='Sample Set Info'!B62 -> 0 | AH7: ='Sample Set Info'!B63 -> 0 | AI7: ='Sample Set Info'!B64 -> 0 | AJ7: ='Sample Set Info'!B65 -> 0 | AK7: ='Sample Set Info'!B66 -> 0 | AL7: ='Sample Set Info'!B67 -> 0 | AM7: ='Sample Set Info'!B68 -> 0 | AN7: ='Sample Set Info'!B69 -> 0 | AO7: ='Sample Set Info'!B70 -> 0 | AP7: ='Sample Set Info'!B71 -> 0 | AQ7: ='Sample Set Info'!B72 -> 0 | AR7: ='Sample Set Info'!B73 -> 0 | AS7: ='Sample Set Info'!B74 -> 0 | AT7: ='Sample Set Info'!B75 -> 0 | AU7: ='Sample Set Info'!B76 -> 0 | AV7: ='Sample Set Info'!B77 -> 0 | AW7: ='Sample Set Info'!B78 -> 0 | AX7: ='Sample Set Info'!B79 -> 0 | AY7: ='Sample Set Info'!B80 -> 0 | AZ7: ='Sample Set Info'!B81 -> 0 | BA7: ='Sample Set Info'!B82 -> 0 | BB7: ='Sample Set Info'!B83 -> 0 | BC7: ='Sample Set Info'!B84 -> 0 | BD7: ='Sample Set Info'!B85 -> 0 | BE7: ='Sample Set Info'!B86 -> 0 | BF7: ='Sample Set Info'!B87 -> 0 | BG7: ='Sample Set Info'!B88 -> 0 | BH7: ='Sample Set Info'!B89 -> 0 | BI7: ='Sample Set Info'!B90 -> 0 | BJ7: ='Sample Set Info'!B91 -> 0 | BK7: ='Sample Set Info'!B92 -> 0 | BL7: ='Sample Set Info'!B93 -> 0 | BM7: ='Sample Set Info'!B94 -> 0 | BN7: ='Sample Set Info'!B95 -> 0 | BO7: ='Sample Set Info'!B96 -> 0 | BP7: ='Sample Set Info'!B97 -> 0 | BQ7: ='Sample Set Info'!B98 -> 0 | BR7: ='Sample Set Info'!B99 -> 0 | BS7: ='Sample Set Info'!B100 -> 0 | BT7: ='Sample Set Info'!B101 -> 0 | BU7: ='Sample Set Info'!B102 -> 0 | BV7: ='Sample Set Info'!B103 -> 0 | BW7: ='Sample Set Info'!B104 -> 0 | BX7: ='Sample Set Info'!B105 -> 0 | BY7: ='Sample Set Info'!B106 -> 0 | BZ7: ='Sample Set Info'!B107 -> 0 | CA7: ='Sample Set Info'!B108 -> 0 | CB7: ='Sample Set Info'!B109 -> 0 | CC7: ='Sample Set Info'!B110 -> 0 | CD7: ='Sample Set Info'!B111 -> 0 | CE7: ='Sample Set Info'!B112 -> 0 | CF7: ='Sample Set Info'!B113 -> 0 | CG7: ='Sample Set Info'!B114 -> 0 | CH7: ='Sample Set Info'!B115 -> 0 | CI7: ='Sample Set Info'!B116 -> 0 | CJ7: ='Sample Set Info'!B117 -> 0 | CK7: ='Sample Set Info'!B118 -> 0 | CL7: ='Sample Set Info'!B119 -> 0 | CM7: ='Sample Set Info'!B120 -> 0 | CN7: ='Sample Set Info'!B121 -> 0 | CO7: ='Sample Set Info'!B122 -> 0 | CP7: ='Sample Set Info'!B123 -> 0 | CQ7: ='Sample Set Info'!B124 -> 0 | CR7: ='Sample Set Info'!B125 -> 0 | CS7: ='Sample Set Info'!B126 -> 0 | CT7: ='Sample Set Info'!B127 -> 0 | CU7: ='Sample Set Info'!B128 -> 0 | CV7: ='Sample Set Info'!B129 -> 0 | CW7: ='Sample Set Info'!B130 -> 0 | CX7: ='Sample Set Info'!B131 -> 0 | CY7: ='Sample Set Info'!B132 -> 0 | CZ7: ='Sample Set Info'!B133 -> 0 | DA7: ='Sample Set Info'!B134 -> 0 | DB7: ='Sample Set Info'!B135 -> 0 | DC7: ='Sample Set Info'!B136 -> 0 | DD7: ='Sample Set Info'!B137 -> 0 | DE7: ='Sample Set Info'!B138 -> 0 | DF7: ='Sample Set Info'!B139 -> 0 | DG7: ='Sample Set Info'!B140 -> 0 | DH7: ='Sample Set Info'!B141 -> 0 | DI7: ='Sample Set Info'!B142 -> 0 | DJ7: ='Sample Set Info'!B143 -> 0 | DK7: ='Sample Set Info'!B144 -> 0 | DL7: ='Sample Set Info'!B145 -> 0 | DM7: ='Sample Set Info'!B146 -> 0 | DN7: ='Sample Set Info'!B147 -> 0 | DO7: ='Sample Set Info'!B148 -> 0 | DP7: ='Sample Set Info'!B149 -> 0 | DQ7: ='Sample Set Info'!B150 -> 0 | DR7: ='Sample Set Info'!B151 -> 0 | DS7: ='Sample Set Info'!B152 -> 0 | DT7: ='Sample Set Info'!B153 -> 0 | DU7: ='Sample Set Info'!B154 -> 0 | DV7: ='Sample Set Info'!B155 -> 0 | DW7: ='Sample Set Info'!B156 -> 0 | DX7: ='Sample Set Info'!B157 -> 0 | DY7: ='Sample Set Info'!B158 -> 0 | DZ7: ='Sample Set Info'!B159 -> 0 | EA7: ='Sample Set Info'!B160 -> 0 | EB7: ='Sample Set Info'!B161 -> 0 | EC7: ='Sample Set Info'!B162 -> 0 | ED7: ='Sample Set Info'!B163 -> 0 | EE7: ='Sample Set Info'!B164 -> 0 | EF7: ='Sample Set Info'!B165 -> 0 | EG7: ='Sample Set Info'!B166 -> 0 | EH7: ='Sample Set Info'!B167 -> 0 | EI7: ='Sample Set Info'!B168 -> 0 | EJ7: ='Sample Set Info'!B169 -> 0 | EK7: ='Sample Set Info'!B170 -> 0 | EL7: ='Sample Set Info'!B171 -> 0 | EM7: ='Sample Set Info'!B172 -> 0 | EN7: ='Sample Set Info'!B173 -> 0 | EO7: ='Sample Set Info'!B174 -> 0 | EP7: ='Sample Set Info'!B175 -> 0 | EQ7: ='Sample Set Info'!B176 -> 0 | ER7: ='Sample Set Info'!B177 -> 0 | ES7: ='Sample Set Info'!B178 -> 0 | ET7: ='Sample Set Info'!B179 -> 0 | EU7: ='Sample Set Info'!B180 -> 0 | EV7: ='Sample Set Info'!B181 -> 0
A8: 2-Methylnapthalene | B8: ='Analyte List'!K28 -> 0 | C8: ='Sample Conc Calc'!AF452 -> #DIV/0!
A9: 1-Methylnapthalene | B9: ='Analyte List'!K29 -> 0 | C9: ='Sample Conc Calc'!AF453 -> #DIV/0!
A10: C2-Naphthalene | B10: ='Analyte List'!K30 -> 0 | C10: ='Sample Conc Calc'!AF454 -> #DIV/0!
A11: C3-Naphthalene | B11: ='Analyte List'!K34 -> 0 | C11: ='Sample Conc Calc'!AF458 -> #DIV/0!
A12: C2-Fluorene | B12: ='Analyte List'!K36 -> 0 | C12: ='Sample Conc Calc'!AF460 -> #DIV/0!
A13: C4 Naphthalene | B13: ='Analyte List'!K41 -> 0 | C13: ='Sample Conc Calc'!AF465 -> #DIV/0!
A14: C1-Fluorene | B14: ='Analyte List'!K43 -> 0 | C14: ='Sample Conc Calc'!AF467 -> #DIV/0!
A15: Dibenzothiophene | B15: ='Analyte List'!K45 -> 0 | C15: ='Sample Conc Calc'!AF469 -> #DIV/0!
A16: C3-Fluorene | B16: ='Analyte List'!K48 -> 0 | C16: ='Sample Conc Calc'!AF472 -> #DIV/0!
A17: C4-Fluorene | B17: ='Analyte List'!K53 -> 0 | C17: ='Sample Conc Calc'!AF477 -> #DIV/0!
A18: C1-Dibenzothiophene | B18: ='Analyte List'!K55 -> 0 | C18: ='Sample Conc Calc'!AF479 -> #DIV/0!
A19: 3-Methylphenanthrene | B19: ='Analyte List'!K58 -> 0 | C19: ='Sample Conc Calc'!AF482 -> #DIV/0!
A20: C1-Phenanthrene / C1-Anthacene | B20: ='Analyte List'!K59 -> 0 | C20: ='Sample Conc Calc'!AF483 -> #VALUE!
A21: 9/4-Methylphenanthrene | B21: ='Analyte List'!K61 -> 0 | C21: ='Sample Conc Calc'!AF485 -> #DIV/0!
A22: 1-Methylphenanthrene | B22: ='Analyte List'!K62 -> 0 | C22: ='Sample Conc Calc'!AF486 -> #DIV/0!
A23: 3,6-Dimethylphenanthrene | B23: ='Analyte List'!K63 -> 0 | C23: ='Sample Conc Calc'!AF487 -> #DIV/0!
A24: 2,6-Dimethylphenanthrene | B24: ='Analyte List'!K64 -> 0 | C24: ='Sample Conc Calc'!AF488 -> #DIV/0!
A25: C2-Phenanthrene / C2-Anthracene | B25: ='Analyte List'!K65 -> 0 | C25: ='Sample Conc Calc'!AF489 -> #DIV/0!
A26: 1,3-Dimethylphenanthrene | B26: ='Analyte List'!K66 -> 0 | C26: ='Sample Conc Calc'!AF490 -> #DIV/0!
A27: C3-Dibenzothiophene | B27: ='Analyte List'!K70 -> 0 | C27: ='Sample Conc Calc'!AF494 -> #VALUE!
A28: ='Analyte List'!A72 -> 3,6-DiMeCar | B28: ='Analyte List'!K72 -> 0 | C28: ='Sample Conc Calc'!AF496 -> #VALUE!
A29: 1,7-Dimethylphenanthrene | B29: ='Analyte List'!K73 -> 0 | C29: ='Sample Conc Calc'!AF497 -> #DIV/0!
A30: C2-Dibenzothiophene | B30: ='Analyte List'!K74 -> 0 | C30: ='Sample Conc Calc'!AF498 -> #DIV/0!
A31: ='Analyte List'!A76 -> 2-Br-DBT | B31: ='Analyte List'!K76 -> 0 | C31: ='Sample Conc Calc'!AF500 -> #VALUE!
A32: 1,8-Dimethylphenanthrene | B32: ='Analyte List'!K77 -> 0 | C32: ='Sample Conc Calc'!AF501 -> #DIV/0!
A33: C4-Dibenzothiophene | B33: ='Analyte List'!K81 -> 0 | C33: ='Sample Conc Calc'!AF505 -> #DIV/0!
A34: C3-Phenanthrene / C3-Anthracene | B34: ='Analyte List'!K85 -> 0 | C34: ='Sample Conc Calc'!AF509 -> #DIV/0!
A35: Retene | B35: ='Analyte List'!K87 -> 0 | C35: ='Sample Conc Calc'!AF511 -> #DIV/0!
A36: C1-Pyrene / C1-Fluoranthene | B36: ='Analyte List'!K88 -> 0 | C36: ='Sample Conc Calc'!AF512 -> #DIV/0!
A37: C4-Phenanthrene / C4-Anthracene | B37: ='Analyte List'!K93 -> 0 | C37: ='Sample Conc Calc'!AF517 -> #DIV/0!
A38: C2-Pyrene / C2-Fluoranthene | B38: ='Analyte List'!K95 -> 0 | C38: ='Sample Conc Calc'!AF519 -> #DIV/0!
A39: Benzo(b)naphtho(1,2-d)thiophene | B39: ='Analyte List'!K97 -> 0 | C39: ='Sample Conc Calc'!AF521 -> #DIV/0!
A40: Benzo(b)naphtho(2,3-d)thiophene | B40: ='Analyte List'!K98 -> 0 | C40: ='Sample Conc Calc'!AF522 -> #DIV/0!
A41: C3-Pyrene / C3-Fluoranthene | B41: ='Analyte List'!K101 -> 0 | C41: ='Sample Conc Calc'!AF525 -> #DIV/0!
A42: C4-Pyrene / C4-Fluoranthene | B42: ='Analyte List'!K106 -> 0 | C42: ='Sample Conc Calc'!AF530 -> #DIV/0!
...

Sheet Results-HPACs
A1: ='Cover Page'!B2 -> Report Title | B1: ='Cover Page'!C2 -> 0
A2: ='Cover Page'!B3 -> Report Number | B2: ='Cover Page'!C3 -> 0
A3: ='Cover Page'!B4 -> Revision | B3: ='Cover Page'!C4 -> 0
A6: Analyte | B6: Limit of Detection (add units)* | C6: Sample Concentration (add units) | M6: =C6 -> Sample Concentration (add units) | X6: =C6 -> Sample Concentration (add units) | AI6: =C6 -> Sample Concentration (add units) | AT6: =C6 -> Sample Concentration (add units) | BE6: =C6 -> Sample Concentration (add units) | BP6: =C6 -> Sample Concentration (add units) | CA6: =C6 -> Sample Concentration (add units) | CL6: =C6 -> Sample Concentration (add units) | CY6: =C6 -> Sample Concentration (add units) | DL6: =C6 -> Sample Concentration (add units) | DY6: =C6 -> Sample Concentration (add units) | EL6: =C6 -> Sample Concentration (add units)
C7: ='Sample Set Info'!B32 -> 0 | D7: ='Sample Set Info'!B33 -> 0 | E7: ='Sample Set Info'!B34 -> 0 | F7: ='Sample Set Info'!B35 -> 0 | G7: ='Sample Set Info'!B36 -> 0 | H7: ='Sample Set Info'!B37 -> 0 | I7: ='Sample Set Info'!B38 -> 0 | J7: ='Sample Set Info'!B39 -> 0 | K7: ='Sample Set Info'!B40 -> 0 | L7: ='Sample Set Info'!B41 -> 0 | M7: ='Sample Set Info'!B42 -> 0 | N7: ='Sample Set Info'!B43 -> 0 | O7: ='Sample Set Info'!B44 -> 0 | P7: ='Sample Set Info'!B45 -> 0 | Q7: ='Sample Set Info'!B46 -> 0 | R7: ='Sample Set Info'!B47 -> 0 | S7: ='Sample Set Info'!B48 -> 0 | T7: ='Sample Set Info'!B49 -> 0 | U7: ='Sample Set Info'!B50 -> 0 | V7: ='Sample Set Info'!B51 -> 0 | W7: ='Sample Set Info'!B52 -> 0 | X7: ='Sample Set Info'!B53 -> 0 | Y7: ='Sample Set Info'!B54 -> 0 | Z7: ='Sample Set Info'!B55 -> 0 | AA7: ='Sample Set Info'!B56 -> 0 | AB7: ='Sample Set Info'!B57 -> 0 | AC7: ='Sample Set Info'!B58 -> 0 | AD7: ='Sample Set Info'!B59 -> 0 | AE7: ='Sample Set Info'!B60 -> 0 | AF7: ='Sample Set Info'!B61 -> 0 | AG7: ='Sample Set Info'!B62 -> 0 | AH7: ='Sample Set Info'!B63 -> 0 | AI7: ='Sample Set Info'!B64 -> 0 | AJ7: ='Sample Set Info'!B65 -> 0 | AK7: ='Sample Set Info'!B66 -> 0 | AL7: ='Sample Set Info'!B67 -> 0 | AM7: ='Sample Set Info'!B68 -> 0 | AN7: ='Sample Set Info'!B69 -> 0 | AO7: ='Sample Set Info'!B70 -> 0 | AP7: ='Sample Set Info'!B71 -> 0 | AQ7: ='Sample Set Info'!B72 -> 0 | AR7: ='Sample Set Info'!B73 -> 0 | AS7: ='Sample Set Info'!B74 -> 0 | AT7: ='Sample Set Info'!B75 -> 0 | AU7: ='Sample Set Info'!B76 -> 0 | AV7: ='Sample Set Info'!B77 -> 0 | AW7: ='Sample Set Info'!B78 -> 0 | AX7: ='Sample Set Info'!B79 -> 0 | AY7: ='Sample Set Info'!B80 -> 0 | AZ7: ='Sample Set Info'!B81 -> 0 | BA7: ='Sample Set Info'!B82 -> 0 | BB7: ='Sample Set Info'!B83 -> 0 | BC7: ='Sample Set Info'!B84 -> 0 | BD7: ='Sample Set Info'!B85 -> 0 | BE7: ='Sample Set Info'!B86 -> 0 | BF7: ='Sample Set Info'!B87 -> 0 | BG7: ='Sample Set Info'!B88 -> 0 | BH7: ='Sample Set Info'!B89 -> 0 | BI7: ='Sample Set Info'!B90 -> 0 | BJ7: ='Sample Set Info'!B91 -> 0 | BK7: ='Sample Set Info'!B92 -> 0 | BL7: ='Sample Set Info'!B93 -> 0 | BM7: ='Sample Set Info'!B94 -> 0 | BN7: ='Sample Set Info'!B95 -> 0 | BO7: ='Sample Set Info'!B96 -> 0 | BP7: ='Sample Set Info'!B97 -> 0 | BQ7: ='Sample Set Info'!B98 -> 0 | BR7: ='Sample Set Info'!B99 -> 0 | BS7: ='Sample Set Info'!B100 -> 0 | BT7: ='Sample Set Info'!B101 -> 0 | BU7: ='Sample Set Info'!B102 -> 0 | BV7: ='Sample Set Info'!B103 -> 0 | BW7: ='Sample Set Info'!B104 -> 0 | BX7: ='Sample Set Info'!B105 -> 0 | BY7: ='Sample Set Info'!B106 -> 0 | BZ7: ='Sample Set Info'!B107 -> 0 | CA7: ='Sample Set Info'!B108 -> 0 | CB7: ='Sample Set Info'!B109 -> 0 | CC7: ='Sample Set Info'!B110 -> 0 | CD7: ='Sample Set Info'!B111 -> 0 | CE7: ='Sample Set Info'!B112 -> 0 | CF7: ='Sample Set Info'!B113 -> 0 | CG7: ='Sample Set Info'!B114 -> 0 | CH7: ='Sample Set Info'!B115 -> 0 | CI7: ='Sample Set Info'!B116 -> 0 | CJ7: ='Sample Set Info'!B117 -> 0 | CK7: ='Sample Set Info'!B118 -> 0 | CL7: ='Sample Set Info'!B119 -> 0 | CM7: ='Sample Set Info'!B120 -> 0 | CN7: ='Sample Set Info'!B121 -> 0 | CO7: ='Sample Set Info'!B122 -> 0 | CP7: ='Sample Set Info'!B123 -> 0 | CQ7: ='Sample Set Info'!B124 -> 0 | CR7: ='Sample Set Info'!B125 -> 0 | CS7: ='Sample Set Info'!B126 -> 0 | CT7: ='Sample Set Info'!B127 -> 0 | CU7: ='Sample Set Info'!B128 -> 0 | CV7: ='Sample Set Info'!B129 -> 0 | CW7: ='Sample Set Info'!B130 -> 0 | CX7: ='Sample Set Info'!B131 -> 0 | CY7: ='Sample Set Info'!B132 -> 0 | CZ7: ='Sample Set Info'!B133 -> 0 | DA7: ='Sample Set Info'!B134 -> 0 | DB7: ='Sample Set Info'!B135 -> 0 | DC7: ='Sample Set Info'!B136 -> 0 | DD7: ='Sample Set Info'!B137 -> 0 | DE7: ='Sample Set Info'!B138 -> 0 | DF7: ='Sample Set Info'!B139 -> 0 | DG7: ='Sample Set Info'!B140 -> 0 | DH7: ='Sample Set Info'!B141 -> 0 | DI7: ='Sample Set Info'!B142 -> 0 | DJ7: ='Sample Set Info'!B143 -> 0 | DK7: ='Sample Set Info'!B144 -> 0 | DL7: ='Sample Set Info'!B145 -> 0 | DM7: ='Sample Set Info'!B146 -> 0 | DN7: ='Sample Set Info'!B147 -> 0 | DO7: ='Sample Set Info'!B148 -> 0 | DP7: ='Sample Set Info'!B149 -> 0 | DQ7: ='Sample Set Info'!B150 -> 0 | DR7: ='Sample Set Info'!B151 -> 0 | DS7: ='Sample Set Info'!B152 -> 0 | DT7: ='Sample Set Info'!B153 -> 0 | DU7: ='Sample Set Info'!B154 -> 0 | DV7: ='Sample Set Info'!B155 -> 0 | DW7: ='Sample Set Info'!B156 -> 0 | DX7: ='Sample Set Info'!B157 -> 0 | DY7: ='Sample Set Info'!B158 -> 0 | DZ7: ='Sample Set Info'!B159 -> 0 | EA7: ='Sample Set Info'!B160 -> 0 | EB7: ='Sample Set Info'!B161 -> 0 | EC7: ='Sample Set Info'!B162 -> 0 | ED7: ='Sample Set Info'!B163 -> 0 | EE7: ='Sample Set Info'!B164 -> 0 | EF7: ='Sample Set Info'!B165 -> 0 | EG7: ='Sample Set Info'!B166 -> 0 | EH7: ='Sample Set Info'!B167 -> 0 | EI7: ='Sample Set Info'!B168 -> 0 | EJ7: ='Sample Set Info'!B169 -> 0 | EK7: ='Sample Set Info'!B170 -> 0 | EL7: ='Sample Set Info'!B171 -> 0 | EM7: ='Sample Set Info'!B172 -> 0 | EN7: ='Sample Set Info'!B173 -> 0 | EO7: ='Sample Set Info'!B174 -> 0 | EP7: ='Sample Set Info'!B175 -> 0 | EQ7: ='Sample Set Info'!B176 -> 0 | ER7: ='Sample Set Info'!B177 -> 0 | ES7: ='Sample Set Info'!B178 -> 0 | ET7: ='Sample Set Info'!B179 -> 0 | EU7: ='Sample Set Info'!B180 -> 0 | EV7: ='Sample Set Info'!B181 -> 0
A8: ='Analyte List'!A128 -> 2,3-Dibromothiophene | B8: ='Analyte List'!K128 -> 0 | C8: ='Sample Conc Calc'!AF552 -> #VALUE! | D8: ='Sample Conc Calc'!AG552 -> #VALUE! | E8: ='Sample Conc Calc'!AH552 -> #VALUE! | F8: ='Sample Conc Calc'!AI552 -> #VALUE! | G8: ='Sample Conc Calc'!AJ552 -> #VALUE! | H8: ='Sample Conc Calc'!AK552 -> #VALUE! | I8: ='Sample Conc Calc'!AL552 -> #VALUE! | J8: ='Sample Conc Calc'!AM552 -> #VALUE! | ... EV8: ='Sample Conc Calc'!FY552 -> #DIV/0!
A9: ='Analyte List'!A129 -> Quinoline | B9: ='Analyte List'!K129 -> 0 | C9: ='Sample Conc Calc'!AF553 -> #DIV/0! | D9: ='Sample Conc Calc'!AG553 -> #DIV/0! | E9: ='Sample Conc Calc'!AH553 -> #DIV/0! | F9: ='Sample Conc Calc'!AI553 -> #DIV/0! | G9: ='Sample Conc Calc'!AJ553 -> #DIV/0! | H9: ='Sample Conc Calc'!AK553 -> #DIV/0! | I9: ='Sample Conc Calc'!AL553 -> #DIV/0! | J9: ='Sample Conc Calc'!AM553 -> #DIV/0! | ... EV9: ='Sample Conc Calc'!FY553 -> #DIV/0!
A10: ='Analyte List'!A130 -> Isoquinoline | B10: ='Analyte List'!K130 -> 0 | C10: ='Sample Conc Calc'!AF554 -> #DIV/0! | D10: ='Sample Conc Calc'!AG554 -> #DIV/0! | E10: ='Sample Conc Calc'!AH554 -> #DIV/0! | F10: ='Sample Conc Calc'!AI554 -> #DIV/0! | G10: ='Sample Conc Calc'!AJ554 -> #DIV/0! | H10: ='Sample Conc Calc'!AK554 -> #DIV/0! | I10: ='Sample Conc Calc'!AL554 -> #DIV/0! | J10: ='Sample Conc Calc'!AM554 -> #DIV/0! | ... EV10: ='Sample Conc Calc'!FY554 -> #DIV/0!
A11: ='Analyte List'!A131 -> Indole | B11: ='Analyte List'!K131 -> 0 | C11: ='Sample Conc Calc'!AF555 -> #DIV/0! | D11: ='Sample Conc Calc'!AG555 -> #DIV/0! | E11: ='Sample Conc Calc'!AH555 -> #DIV/0! | F11: ='Sample Conc Calc'!AI555 -> #DIV/0! | G11: ='Sample Conc Calc'!AJ555 -> #DIV/0! | H11: ='Sample Conc Calc'!AK555 -> #DIV/0! | I11: ='Sample Conc Calc'!AL555 -> #DIV/0! | J11: ='Sample Conc Calc'!AM555 -> #DIV/0! | ... EV11: ='Sample Conc Calc'!FY555 -> #DIV/0!
A12: ='Analyte List'!A132 -> Methylquinoline 2-Mequinoline | B12: ='Analyte List'!K132 -> 0 | C12: ='Sample Conc Calc'!AF556 -> #DIV/0! | D12: ='Sample Conc Calc'!AG556 -> #DIV/0! | E12: ='Sample Conc Calc'!AH556 -> #DIV/0! | F12: ='Sample Conc Calc'!AI556 -> #DIV/0! | G12: ='Sample Conc Calc'!AJ556 -> #DIV/0! | H12: ='Sample Conc Calc'!AK556 -> #DIV/0! | I12: ='Sample Conc Calc'!AL556 -> #DIV/0! | J12: ='Sample Conc Calc'!AM556 -> #DIV/0! | ... EV12: ='Sample Conc Calc'!FY556 -> #DIV/0!
A13: ='Analyte List'!A133 -> 4-Methylbenzothiophene | B13: ='Analyte List'!K133 -> 0 | C13: ='Sample Conc Calc'!AF557 -> #DIV/0! | D13: ='Sample Conc Calc'!AG557 -> #DIV/0! | E13: ='Sample Conc Calc'!AH557 -> #DIV/0! | F13: ='Sample Conc Calc'!AI557 -> #DIV/0! | G13: ='Sample Conc Calc'!AJ557 -> #DIV/0! | H13: ='Sample Conc Calc'!AK557 -> #DIV/0! | I13: ='Sample Conc Calc'!AL557 -> #DIV/0! | J13: ='Sample Conc Calc'!AM557 -> #DIV/0! | ... EV13: ='Sample Conc Calc'!FY557 -> #DIV/0!
A14: ='Analyte List'!A134 -> Methylquinoline 3-Meisoquinoline | B14: ='Analyte List'!K134 -> 0 | C14: ='Sample Conc Calc'!AF558 -> #DIV/0! | D14: ='Sample Conc Calc'!AG558 -> #DIV/0! | E14: ='Sample Conc Calc'!AH558 -> #DIV/0! | F14: ='Sample Conc Calc'!AI558 -> #DIV/0! | G14: ='Sample Conc Calc'!AJ558 -> #DIV/0! | H14: ='Sample Conc Calc'!AK558 -> #DIV/0! | I14: ='Sample Conc Calc'!AL558 -> #DIV/0! | J14: ='Sample Conc Calc'!AM558 -> #DIV/0! | ... EV14: ='Sample Conc Calc'!FY558 -> #DIV/0!
A15: ='Analyte List'!A135 -> 5-chlorobenzothiophene | B15: ='Analyte List'!K135 -> 0 | C15: ='Sample Conc Calc'!AF559 -> #VALUE! | D15: ='Sample Conc Calc'!AG559 -> #VALUE! | E15: ='Sample Conc Calc'!AH559 -> #VALUE! | F15: ='Sample Conc Calc'!AI559 -> #VALUE! | G15: ='Sample Conc Calc'!AJ559 -> #VALUE! | H15: ='Sample Conc Calc'!AK559 -> #VALUE! | I15: ='Sample Conc Calc'!AL559 -> #VALUE! | J15: ='Sample Conc Calc'!AM559 -> #VALUE! | ... EV15: ='Sample Conc Calc'!FY559 -> #DIV/0!
A16: ='Analyte List'!A136 -> 2,3-Dimethylbenzothiophene | B16: ='Analyte List'!K136 -> 0 | C16: ='Sample Conc Calc'!AF560 -> #DIV/0! | D16: ='Sample Conc Calc'!AG560 -> #DIV/0! | E16: ='Sample Conc Calc'!AH560 -> #DIV/0! | F16: ='Sample Conc Calc'!AI560 -> #DIV/0! | G16: ='Sample Conc Calc'!AJ560 -> #DIV/0! | H16: ='Sample Conc Calc'!AK560 -> #DIV/0! | I16: ='Sample Conc Calc'!AL560 -> #DIV/0! | J16: ='Sample Conc Calc'!AM560 -> #DIV/0! | ... EV16: ='Sample Conc Calc'!FY560 -> #DIV/0!
A17: ='Analyte List'!A137 -> 2-Chloroquinoline | B17: ='Analyte List'!K137 -> 0 | C17: ='Sample Conc Calc'!AF561 -> #DIV/0! | D17: ='Sample Conc Calc'!AG561 -> #DIV/0! | E17: ='Sample Conc Calc'!AH561 -> #DIV/0! | F17: ='Sample Conc Calc'!AI561 -> #DIV/0! | G17: ='Sample Conc Calc'!AJ561 -> #DIV/0! | H17: ='Sample Conc Calc'!AK561 -> #DIV/0! | I17: ='Sample Conc Calc'!AL561 -> #DIV/0! | J17: ='Sample Conc Calc'!AM561 -> #DIV/0! | ... EV17: ='Sample Conc Calc'!FY561 -> #DIV/0!
A18: ='Analyte List'!A138 -> 2-Bromobenzothiophene | B18: ='Analyte List'!K138 -> 0 | C18: ='Sample Conc Calc'!AF562 -> #DIV/0! | D18: ='Sample Conc Calc'!AG562 -> #DIV/0! | E18: ='Sample Conc Calc'!AH562 -> #DIV/0! | F18: ='Sample Conc Calc'!AI562 -> #DIV/0! | G18: ='Sample Conc Calc'!AJ562 -> #DIV/0! | H18: ='Sample Conc Calc'!AK562 -> #DIV/0! | I18: ='Sample Conc Calc'!AL562 -> #DIV/0! | J18: ='Sample Conc Calc'!AM562 -> #DIV/0! | ... EV18: ='Sample Conc Calc'!FY562 -> #DIV/0!
A19: ='Analyte List'!A139 -> 2,3-Dimethylindole | B19: ='Analyte List'!K139 -> 0 | C19: ='Sample Conc Calc'!AF563 -> #DIV/0! | D19: ='Sample Conc Calc'!AG563 -> #DIV/0! | E19: ='Sample Conc Calc'!AH563 -> #DIV/0! | F19: ='Sample Conc Calc'!AI563 -> #DIV/0! | G19: ='Sample Conc Calc'!AJ563 -> #DIV/0! | H19: ='Sample Conc Calc'!AK563 -> #DIV/0! | I19: ='Sample Conc Calc'!AL563 -> #DIV/0! | J19: ='Sample Conc Calc'!AM563 -> #DIV/0! | ... EV19: ='Sample Conc Calc'!FY563 -> #DIV/0!
... A36: ='Analyte List'!A156 -> 9-Chloroacridine | B36: ='Analyte List'!K156 -> 0 | C36: ='Sample Conc Calc'!AF580 -> #DIV/0! | D36: ='Sample Conc Calc'!AG580 -> #DIV/0! | E36: ='Sample Conc Calc'!AH580 -> #DIV/0! | F36: ='Sample Conc Calc'!AI580 -> #DIV/0! | G36: ='Sample Conc Calc'!AJ580 -> #DIV/0! | H36: ='Sample Conc Calc'!AK580 -> #DIV/0! | I36: ='Sample Conc Calc'!AL580 -> #DIV/0! | J36: ='Sample Conc Calc'!AM580 -> #DIV/0! | ... EV36: ='Sample Conc Calc'!FY580 -> #DIV/0!
A37: ='Analyte List'!A157 -> 9-bromoacridine | B37: ='Analyte List'!K158 -> 0 | C37: ='Sample Conc Calc'!AF581 -> #DIV/0! | D37: ='Sample Conc Calc'!AG581 -> #DIV/0! | E37: ='Sample Conc Calc'!AH581 -> #DIV/0! | F37: ='Sample Conc Calc'!AI581 -> #DIV/0! | G37: ='Sample Conc Calc'!AJ581 -> #DIV/0! | H37: ='Sample Conc Calc'!AK581 -> #DIV/0! | I37: ='Sample Conc Calc'!AL581 -> #DIV/0! | J37: ='Sample Conc Calc'!AM581 -> #DIV/0! | ... EV37: ='Sample Conc Calc'!FY581 -> #DIV/0!
A38: ='Analyte List'!A158 -> 2-Bromodibenzothiophene | B38: ='Analyte List'!K157 -> 0 | C38: ='Sample Conc Calc'!AF582 -> #DIV/0! | D38: ='Sample Conc Calc'!AG582 -> #DIV/0! | E38: ='Sample Conc Calc'!AH582 -> #DIV/0! | F38: ='Sample Conc Calc'!AI582 -> #DIV/0! | G38: ='Sample Conc Calc'!AJ582 -> #DIV/0! | H38: ='Sample Conc Calc'!AK582 -> #DIV/0! | I38: ='Sample Conc Calc'!AL582 -> #DIV/0! | J38: ='Sample Conc Calc'!AM582 -> #DIV/0! | ... EV38: ='Sample Conc Calc'!FY582 -> #DIV/0!
A39: ='Analyte List'!A159 -> Benzo[b]naphtho[2,3-d]furan | B39: ='Analyte List'!K159 -> 0 | C39: ='Sample Conc Calc'!AF583 -> #DIV/0! | D39: ='Sample Conc Calc'!AG583 -> #DIV/0! | E39: ='Sample Conc Calc'!AH583 -> #DIV/0! | F39: ='Sample Conc Calc'!AI583 -> #DIV/0! | G39: ='Sample Conc Calc'!AJ583 -> #DIV/0! | H39: ='Sample Conc Calc'!AK583 -> #DIV/0! | I39: ='Sample Conc Calc'!AL583 -> #DIV/0! | J39: ='Sample Conc Calc'!AM583 -> #DIV/0! | ... EV39: ='Sample Conc Calc'!FY583 -> #DIV/0!
A40: ='Analyte List'!A160 -> 3-Tert-butyl-9H-carbazole | B40: ='Analyte List'!K160 -> 0 | C40: ='Sample Conc Calc'!AF584 -> #DIV/0! | D40: ='Sample Conc Calc'!AG584 -> #DIV/0! | E40: ='Sample Conc Calc'!AH584 -> #DIV/0! | F40: ='Sample Conc Calc'!AI584 -> #DIV/0! | G40: ='Sample Conc Calc'!AJ584 -> #DIV/0! | H40: ='Sample Conc Calc'!AK584 -> #DIV/0! | I40: ='Sample Conc Calc'!AL584 -> #DIV/0! | J40: ='Sample Conc Calc'!AM584 -> #DIV/0! | ... EV40: ='Sample Conc Calc'!FY584 -> #DIV/0!
A41: ='Analyte List'!A161 -> 9-Phenylcarbazole | B41: ='Analyte List'!K161 -> 0 | C41: ='Sample Conc Calc'!AF585 -> #DIV/0! | D41: ='Sample Conc Calc'!AG585 -> #DIV/0! | E41: ='Sample Conc Calc'!AH585 -> #DIV/0! | F41: ='Sample Conc Calc'!AI585 -> #DIV/0! | G41: ='Sample Conc Calc'!AJ585 -> #DIV/0! | H41: ='Sample Conc Calc'!AK585 -> #DIV/0! | I41: ='Sample Conc Calc'!AL585 -> #DIV/0! | J41: ='Sample Conc Calc'!AM585 -> #DIV/0! | ... EV41: ='Sample Conc Calc'!FY585 -> #DIV/0!
A42: ='Analyte List'!A162 -> 3,6-Dichloro-9h-carbazole | B42: ='Analyte List'!K162 -> 0 | C42: ='Sample Conc Calc'!AF586 -> #DIV/0! | D42: ='Sample Conc Calc'!AG586 -> #DIV/0! | E42: ='Sample Conc Calc'!AH586 -> #DIV/0! | F42: ='Sample Conc Calc'!AI586 -> #DIV/0! | G42: ='Sample Conc Calc'!AJ586 -> #DIV/0! | H42: ='Sample Conc Calc'!AK586 -> #DIV/0! | I42: ='Sample Conc Calc'!AL586 -> #DIV/0! | J42: ='Sample Conc Calc'!AM586 -> #DIV/0! | ... EV42: ='Sample Conc Calc'!FY586 -> #DIV/0!
A43: ='Analyte List'!A163 -> 7,8,9,10-Tetrahydrobenzo[b]naphtho[2,3-d]thiophene | B43: ='Analyte List'!K163 -> 0 | C43: ='Sample Conc Calc'!AF587 -> #DIV/0! | D43: ='Sample Conc Calc'!AG587 -> #DIV/0! | E43: ='Sample Conc Calc'!AH587 -> #DIV/0! | F43: ='Sample Conc Calc'!AI587 -> #DIV/0! | G43: ='Sample Conc Calc'!AJ587 -> #DIV/0! | H43: ='Sample Conc Calc'!AK587 -> #DIV/0! | I43: ='Sample Conc Calc'!AL587 -> #DIV/0! | J43: ='Sample Conc Calc'!AM587 -> #DIV/0! | ... EV43: ='Sample Conc Calc'!FY587 -> #DIV/0!
A44: ='Analyte List'!A164 -> 2,8-Dibromodibenzothiophene | B44: ='Analyte List'!K164 -> 0 | C44: ='Sample Conc Calc'!AF588 -> #DIV/0! | D44: ='Sample Conc Calc'!AG588 -> #DIV/0! | E44: ='Sample Conc Calc'!AH588 -> #DIV/0! | F44: ='Sample Conc Calc'!AI588 -> #DIV/0! | G44: ='Sample Conc Calc'!AJ588 -> #DIV/0! | H44: ='Sample Conc Calc'!AK588 -> #DIV/0! | I44: ='Sample Conc Calc'!AL588 -> #DIV/0! | J44: ='Sample Conc Calc'!AM588 -> #DIV/0! | ... EV44: ='Sample Conc Calc'!FY588 -> #DIV/0!
A45: ='Analyte List'!A165 -> Benz[c]acridine | B45: ='Analyte List'!K165 -> 0 | C45: ='Sample Conc Calc'!AF589 -> #DIV/0! | D45: ='Sample Conc Calc'!AG589 -> #DIV/0! | E45: ='Sample Conc Calc'!AH589 -> #DIV/0! | F45: ='Sample Conc Calc'!AI589 -> #DIV/0! | G45: ='Sample Conc Calc'!AJ589 -> #DIV/0! | H45: ='Sample Conc Calc'!AK589 -> #DIV/0! | I45: ='Sample Conc Calc'!AL589 -> #DIV/0! | J45: ='Sample Conc Calc'!AM589 -> #DIV/0! | ... EV45: ='Sample Conc Calc'!FY589 -> #DIV/0!
A46: ='Analyte List'!A166 -> 11H-Benzo[a]carbazole | B46: ='Analyte List'!K166 -> 0 | C46: ='Sample Conc Calc'!AF590 -> #DIV/0! | D46: ='Sample Conc Calc'!AG590 -> #DIV/0! | E46: ='Sample Conc Calc'!AH590 -> #DIV/0! | F46: ='Sample Conc Calc'!AI590 -> #DIV/0! | G46: ='Sample Conc Calc'!AJ590 -> #DIV/0! | H46: ='Sample Conc Calc'!AK590 -> #DIV/0! | I46: ='Sample Conc Calc'!AL590 -> #DIV/0! | J46: ='Sample Conc Calc'!AM590 -> #DIV/0! | ... EV46: ='Sample Conc Calc'!FY590 -> #DIV/0!
A47: ='Analyte List'!A167 -> 7H-benzo[c]carbazole | B47: ='Analyte List'!K167 -> 0 | C47: ='Sample Conc Calc'!AF591 -> #DIV/0! | D47: ='Sample Conc Calc'!AG591 -> #DIV/0! | E47: ='Sample Conc Calc'!AH591 -> #DIV/0! | F47: ='Sample Conc Calc'!AI591 -> #DIV/0! | G47: ='Sample Conc Calc'!AJ591 -> #DIV/0! | H47: ='Sample Conc Calc'!AK591 -> #DIV/0! | I47: ='Sample Conc Calc'!AL591 -> #DIV/0! | J47: ='Sample Conc Calc'!AM591 -> #DIV/0! | ... EV47: ='Sample Conc Calc'!FY591 -> #DIV/0!
A48: ='Analyte List'!A168 -> 6-Methylbenzo [b]naphtho[2,1-d]thiophene | B48: ='Analyte List'!K168 -> 0 | C48: ='Sample Conc Calc'!AF592 -> #DIV/0! | D48: ='Sample Conc Calc'!AG592 -> #DIV/0! | E48: ='Sample Conc Calc'!AH592 -> #DIV/0! | F48: ='Sample Conc Calc'!AI592 -> #DIV/0! | G48: ='Sample Conc Calc'!AJ592 -> #DIV/0! | H48: ='Sample Conc Calc'!AK592 -> #DIV/0! | I48: ='Sample Conc Calc'!AL592 -> #DIV/0! | J48: ='Sample Conc Calc'!AM592 -> #DIV/0! | ... EV48: ='Sample Conc Calc'!FY592 -> #DIV/0!
A49: ='Analyte List'!A169 -> 3,6-Dibromocarbazole | B49: ='Analyte List'!K169 -> 0 | C49: ='Sample Conc Calc'!AF593 -> #DIV/0! | D49: ='Sample Conc Calc'!AG593 -> #DIV/0! | E49: ='Sample Conc Calc'!AH593 -> #DIV/0! | F49: ='Sample Conc Calc'!AI593 -> #DIV/0! | G49: ='Sample Conc Calc'!AJ593 -> #DIV/0! | H49: ='Sample Conc Calc'!AK593 -> #DIV/0! | I49: ='Sample Conc Calc'!AL593 -> #DIV/0! | J49: ='Sample Conc Calc'!AM593 -> #DIV/0! | ... EV49: ='Sample Conc Calc'!FY593 -> #DIV/0!
A50: ='Analyte List'!A170 -> 2-Phenyldibenzothiophene | B50: ='Analyte List'!K170 -> 0 | C50: ='Sample Conc Calc'!AF594 -> #DIV/0! | D50: ='Sample Conc Calc'!AG594 -> #DIV/0! | E50: ='Sample Conc Calc'!AH594 -> #DIV/0! | F50: ='Sample Conc Calc'!AI594 -> #DIV/0! | G50: ='Sample Conc Calc'!AJ594 -> #DIV/0! | H50: ='Sample Conc Calc'!AK594 -> #DIV/0! | I50: ='Sample Conc Calc'!AL594 -> #DIV/0! | J50: ='Sample Conc Calc'!AM594 -> #DIV/0! | ... EV50: ='Sample Conc Calc'!FY594 -> #DIV/0!
... A53: ='Analyte List'!A173 -> 13(H)-Dibenzo[a,i]carbazole | B53: ='Analyte List'!K173 -> 0 | C53: ='Sample Conc Calc'!AF597 -> #DIV/0! | D53: ='Sample Conc Calc'!AG597 -> #DIV/0! | E53: ='Sample Conc Calc'!AH597 -> #DIV/0! | F53: ='Sample Conc Calc'!AI597 -> #DIV/0! | G53: ='Sample Conc Calc'!AJ597 -> #DIV/0! | H53: ='Sample Conc Calc'!AK597 -> #DIV/0! | I53: ='Sample Conc Calc'!AL597 -> #DIV/0! | J53: ='Sample Conc Calc'!AM597 -> #DIV/0! | ... EV53: ='Sample Conc Calc'!FY597 -> #DIV/0!

Sheet Results-HPAHs
A1: ='Cover Page'!B2 -> Report Title | B1: ='Cover Page'!C2 -> 0
A2: ='Cover Page'!B3 -> Report Number | B2: ='Cover Page'!C3 -> 0
A3: ='Cover Page'!B4 -> Revision | B3: ='Cover Page'!C4 -> 0
A6: Analyte | B6: Limit of Detection (add units)* | C6: Sample Concentration (add units) | M6: =C6 -> Sample Concentration (add units) | X6: =C6 -> Sample Concentration (add units) | AI6: =C6 -> Sample Concentration (add units) | AT6: =C6 -> Sample Concentration (add units) | BE6: =C6 -> Sample Concentration (add units) | BP6: =C6 -> Sample Concentration (add units) | CA6: =C6 -> Sample Concentration (add units) | CL6: =C6 -> Sample Concentration (add units) | CY6: =C6 -> Sample Concentration (add units) | DL6: =C6 -> Sample Concentration (add units) | DY6: =C6 -> Sample Concentration (add units) | EL6: =C6 -> Sample Concentration (add units)
C7: ='Sample Set Info'!B32 -> 0 | D7: ='Sample Set Info'!B33 -> 0 | E7: ='Sample Set Info'!B34 -> 0 | F7: ='Sample Set Info'!B35 -> 0 | G7: ='Sample Set Info'!B36 -> 0 | H7: ='Sample Set Info'!B37 -> 0 | I7: ='Sample Set Info'!B38 -> 0 | J7: ='Sample Set Info'!B39 -> 0 | K7: ='Sample Set Info'!B40 -> 0 | L7: ='Sample Set Info'!B41 -> 0 | M7: ='Sample Set Info'!B42 -> 0 | N7: ='Sample Set Info'!B43 -> 0 | O7: ='Sample Set Info'!B44 -> 0 | P7: ='Sample Set Info'!B45 -> 0 | Q7: ='Sample Set Info'!B46 -> 0 | R7: ='Sample Set Info'!B47 -> 0 | S7: ='Sample Set Info'!B48 -> 0 | T7: ='Sample Set Info'!B49 -> 0 | U7: ='Sample Set Info'!B50 -> 0 | V7: ='Sample Set Info'!B51 -> 0 | W7: ='Sample Set Info'!B52 -> 0 | X7: ='Sample Set Info'!B53 -> 0 | Y7: ='Sample Set Info'!B54 -> 0 | Z7: ='Sample Set Info'!B55 -> 0 | AA7: ='Sample Set Info'!B56 -> 0 | AB7: ='Sample Set Info'!B57 -> 0 | AC7: ='Sample Set Info'!B58 -> 0 | AD7: ='Sample Set Info'!B59 -> 0 | AE7: ='Sample Set Info'!B60 -> 0 | AF7: ='Sample Set Info'!B61 -> 0 | AG7: ='Sample Set Info'!B62 -> 0 | AH7: ='Sample Set Info'!B63 -> 0 | AI7: ='Sample Set Info'!B64 -> 0 | AJ7: ='Sample Set Info'!B65 -> 0 | AK7: ='Sample Set Info'!B66 -> 0 | AL7: ='Sample Set Info'!B67 -> 0 | AM7: ='Sample Set Info'!B68 -> 0 | AN7: ='Sample Set Info'!B69 -> 0 | AO7: ='Sample Set Info'!B70 -> 0 | AP7: ='Sample Set Info'!B71 -> 0 | AQ7: ='Sample Set Info'!B72 -> 0 | AR7: ='Sample Set Info'!B73 -> 0 | AS7: ='Sample Set Info'!B74 -> 0 | AT7: ='Sample Set Info'!B75 -> 0 | AU7: ='Sample Set Info'!B76 -> 0 | AV7: ='Sample Set Info'!B77 -> 0 | AW7: ='Sample Set Info'!B78 -> 0 | AX7: ='Sample Set Info'!B79 -> 0 | AY7: ='Sample Set Info'!B80 -> 0 | AZ7: ='Sample Set Info'!B81 -> 0 | BA7: ='Sample Set Info'!B82 -> 0 | BB7: ='Sample Set Info'!B83 -> 0 | BC7: ='Sample Set Info'!B84 -> 0 | BD7: ='Sample Set Info'!B85 -> 0 | BE7: ='Sample Set Info'!B86 -> 0 | BF7: ='Sample Set Info'!B87 -> 0 | BG7: ='Sample Set Info'!B88 -> 0 | BH7: ='Sample Set Info'!B89 -> 0 | BI7: ='Sample Set Info'!B90 -> 0 | BJ7: ='Sample Set Info'!B91 -> 0 | BK7: ='Sample Set Info'!B92 -> 0 | BL7: ='Sample Set Info'!B93 -> 0 | BM7: ='Sample Set Info'!B94 -> 0 | BN7: ='Sample Set Info'!B95 -> 0 | BO7: ='Sample Set Info'!B96 -> 0 | BP7: ='Sample Set Info'!B97 -> 0 | BQ7: ='Sample Set Info'!B98 -> 0 | BR7: ='Sample Set Info'!B99 -> 0 | BS7: ='Sample Set Info'!B100 -> 0 | BT7: ='Sample Set Info'!B101 -> 0 | BU7: ='Sample Set Info'!B102 -> 0 | BV7: ='Sample Set Info'!B103 -> 0 | BW7: ='Sample Set Info'!B104 -> 0 | BX7: ='Sample Set Info'!B105 -> 0 | BY7: ='Sample Set Info'!B106 -> 0 | BZ7: ='Sample Set Info'!B107 -> 0 | CA7: ='Sample Set Info'!B108 -> 0 | CB7: ='Sample Set Info'!B109 -> 0 | CC7: ='Sample Set Info'!B110 -> 0 | CD7: ='Sample Set Info'!B111 -> 0 | CE7: ='Sample Set Info'!B112 -> 0 | CF7: ='Sample Set Info'!B113 -> 0 | CG7: ='Sample Set Info'!B114 -> 0 | CH7: ='Sample Set Info'!B115 -> 0 | CI7: ='Sample Set Info'!B116 -> 0 | CJ7: ='Sample Set Info'!B117 -> 0 | CK7: ='Sample Set Info'!B118 -> 0 | CL7: ='Sample Set Info'!B119 -> 0 | CM7: ='Sample Set Info'!B120 -> 0 | CN7: ='Sample Set Info'!B121 -> 0 | CO7: ='Sample Set Info'!B122 -> 0 | CP7: ='Sample Set Info'!B123 -> 0 | CQ7: ='Sample Set Info'!B124 -> 0 | CR7: ='Sample Set Info'!B125 -> 0 | CS7: ='Sample Set Info'!B126 -> 0 | CT7: ='Sample Set Info'!B127 -> 0 | CU7: ='Sample Set Info'!B128 -> 0 | CV7: ='Sample Set Info'!B129 -> 0 | CW7: ='Sample Set Info'!B130 -> 0 | CX7: ='Sample Set Info'!B131 -> 0 | CY7: ='Sample Set Info'!B132 -> 0 | CZ7: ='Sample Set Info'!B133 -> 0 | DA7: ='Sample Set Info'!B134 -> 0 | DB7: ='Sample Set Info'!B135 -> 0 | DC7: ='Sample Set Info'!B136 -> 0 | DD7: ='Sample Set Info'!B137 -> 0 | DE7: ='Sample Set Info'!B138 -> 0 | DF7: ='Sample Set Info'!B139 -> 0 | DG7: ='Sample Set Info'!B140 -> 0 | DH7: ='Sample Set Info'!B141 -> 0 | DI7: ='Sample Set Info'!B142 -> 0 | DJ7: ='Sample Set Info'!B143 -> 0 | DK7: ='Sample Set Info'!B144 -> 0 | DL7: ='Sample Set Info'!B145 -> 0 | DM7: ='Sample Set Info'!B146 -> 0 | DN7: ='Sample Set Info'!B147 -> 0 | DO7: ='Sample Set Info'!B148 -> 0 | DP7: ='Sample Set Info'!B149 -> 0 | DQ7: ='Sample Set Info'!B150 -> 0 | DR7: ='Sample Set Info'!B151 -> 0 | DS7: ='Sample Set Info'!B152 -> 0 | DT7: ='Sample Set Info'!B153 -> 0 | DU7: ='Sample Set Info'!B154 -> 0 | DV7: ='Sample Set Info'!B155 -> 0 | DW7: ='Sample Set Info'!B156 -> 0 | DX7: ='Sample Set Info'!B157 -> 0 | DY7: ='Sample Set Info'!B158 -> 0 | DZ7: ='Sample Set Info'!B159 -> 0 | EA7: ='Sample Set Info'!B160 -> 0 | EB7: ='Sample Set Info'!B161 -> 0 | EC7: ='Sample Set Info'!B162 -> 0 | ED7: ='Sample Set Info'!B163 -> 0 | EE7: ='Sample Set Info'!B164 -> 0 | EF7: ='Sample Set Info'!B165 -> 0 | EG7: ='Sample Set Info'!B166 -> 0 | EH7: ='Sample Set Info'!B167 -> 0 | EI7: ='Sample Set Info'!B168 -> 0 | EJ7: ='Sample Set Info'!B169 -> 0 | EK7: ='Sample Set Info'!B170 -> 0 | EL7: ='Sample Set Info'!B171 -> 0 | EM7: ='Sample Set Info'!B172 -> 0 | EN7: ='Sample Set Info'!B173 -> 0 | EO7: ='Sample Set Info'!B174 -> 0 | EP7: ='Sample Set Info'!B175 -> 0 | EQ7: ='Sample Set Info'!B176 -> 0 | ER7: ='Sample Set Info'!B177 -> 0 | ES7: ='Sample Set Info'!B178 -> 0 | ET7: ='Sample Set Info'!B179 -> 0 | EU7: ='Sample Set Info'!B180 -> 0 | EV7: ='Sample Set Info'!B181 -> 0
A8: ='Analyte List'!A177 -> 9-Cl-Flu | B8: ='Analyte List'!K177 -> 0 | C8: ='Sample Conc Calc'!AF601 -> #DIV/0! | D8: ='Sample Conc Calc'!AG601 -> #DIV/0! | E8: ='Sample Conc Calc'!AH601 -> #DIV/0! | F8: ='Sample Conc Calc'!AI601 -> #DIV/0! | G8: ='Sample Conc Calc'!AJ601 -> #DIV/0! | H8: ='Sample Conc Calc'!AK601 -> #DIV/0! | I8: ='Sample Conc Calc'!AL601 -> #DIV/0! | J8: ='Sample Conc Calc'!AM601 -> #DIV/0! | ... EV8: ='Sample Conc Calc'!FY601 -> #DIV/0!
A9: ='Analyte List'!A178 -> 2-Cl-Flu | B9: ='Analyte List'!K178 -> 0 | C9: ='Sample Conc Calc'!AF602 -> #DIV/0! | D9: ='Sample Conc Calc'!AG602 -> #DIV/0! | E9: ='Sample Conc Calc'!AH602 -> #DIV/0! | F9: ='Sample Conc Calc'!AI602 -> #DIV/0! | G9: ='Sample Conc Calc'!AJ602 -> #DIV/0! | H9: ='Sample Conc Calc'!AK602 -> #DIV/0! | I9: ='Sample Conc Calc'!AL602 -> #DIV/0! | J9: ='Sample Conc Calc'!AM602 -> #DIV/0! | ... EV9: ='Sample Conc Calc'!FY602 -> #DIV/0!
A10: ='Analyte List'!A179 -> 5-Br-Ace | B10: ='Analyte List'!K179 -> 0 | C10: ='Sample Conc Calc'!AF603 -> #DIV/0! | D10: ='Sample Conc Calc'!AG603 -> #DIV/0! | E10: ='Sample Conc Calc'!AH603 -> #DIV/0! | F10: ='Sample Conc Calc'!AI603 -> #DIV/0! | G10: ='Sample Conc Calc'!AJ603 -> #DIV/0! | H10: ='Sample Conc Calc'!AK603 -> #DIV/0! | I10: ='Sample Conc Calc'!AL603 -> #DIV/0! | J10: ='Sample Conc Calc'!AM603 -> #DIV/0! | ... EV10: ='Sample Conc Calc'!FY603 -> #DIV/0!
A11: ='Analyte List'!A180 -> 9-Br-Flu | B11: ='Analyte List'!K180 -> 0 | C11: ='Sample Conc Calc'!AF604 -> #DIV/0! | D11: ='Sample Conc Calc'!AG604 -> #DIV/0! | E11: ='Sample Conc Calc'!AH604 -> #DIV/0! | F11: ='Sample Conc Calc'!AI604 -> #DIV/0! | G11: ='Sample Conc Calc'!AJ604 -> #DIV/0! | H11: ='Sample Conc Calc'!AK604 -> #DIV/0! | I11: ='Sample Conc Calc'!AL604 -> #DIV/0! | J11: ='Sample Conc Calc'!AM604 -> #DIV/0! | ... EV11: ='Sample Conc Calc'!FY604 -> #DIV/0!
A12: ='Analyte List'!A181 -> 2-Br-Flu | B12: ='Analyte List'!K181 -> 0 | C12: ='Sample Conc Calc'!AF605 -> #VALUE! | D12: ='Sample Conc Calc'!AG605 -> #VALUE! | E12: ='Sample Conc Calc'!AH605 -> #VALUE! | F12: ='Sample Conc Calc'!AI605 -> #VALUE! | G12: ='Sample Conc Calc'!AJ605 -> #VALUE! | H12: ='Sample Conc Calc'!AK605 -> #VALUE! | I12: ='Sample Conc Calc'!AL605 -> #VALUE! | J12: ='Sample Conc Calc'!AM605 -> #VALUE! | ... EV12: ='Sample Conc Calc'!FY605 -> #DIV/0!
A13: ='Analyte List'!A182 -> 1-Cl-Ant | B13: ='Analyte List'!K182 -> 0 | C13: ='Sample Conc Calc'!AF606 -> #DIV/0! | D13: ='Sample Conc Calc'!AG606 -> #DIV/0! | E13: ='Sample Conc Calc'!AH606 -> #DIV/0! | F13: ='Sample Conc Calc'!AI606 -> #DIV/0! | G13: ='Sample Conc Calc'!AJ606 -> #DIV/0! | H13: ='Sample Conc Calc'!AK606 -> #DIV/0! | I13: ='Sample Conc Calc'!AL606 -> #DIV/0! | J13: ='Sample Conc Calc'!AM606 -> #DIV/0! | ... EV13: ='Sample Conc Calc'!FY606 -> #DIV/0!
A14: ='Analyte List'!A183 -> 2,7-Cl2-Flu | B14: ='Analyte List'!K183 -> 0 | C14: ='Sample Conc Calc'!AF607 -> #DIV/0! | D14: ='Sample Conc Calc'!AG607 -> #DIV/0! | E14: ='Sample Conc Calc'!AH607 -> #DIV/0! | F14: ='Sample Conc Calc'!AI607 -> #DIV/0! | G14: ='Sample Conc Calc'!AJ607 -> #DIV/0! | H14: ='Sample Conc Calc'!AK607 -> #DIV/0! | I14: ='Sample Conc Calc'!AL607 -> #DIV/0! | J14: ='Sample Conc Calc'!AM607 -> #DIV/0! | ... EV14: ='Sample Conc Calc'!FY607 -> #DIV/0!
A15: ='Analyte List'!A184 -> 1,2-Br2-Acy | B15: ='Analyte List'!K184 -> 0 | C15: ='Sample Conc Calc'!AF608 -> #VALUE! | D15: ='Sample Conc Calc'!AG608 -> #VALUE! | E15: ='Sample Conc Calc'!AH608 -> #VALUE! | F15: ='Sample Conc Calc'!AI608 -> #VALUE! | G15: ='Sample Conc Calc'!AJ608 -> #VALUE! | H15: ='Sample Conc Calc'!AK608 -> #VALUE! | I15: ='Sample Conc Calc'!AL608 -> #VALUE! | J15: ='Sample Conc Calc'!AM608 -> #VALUE! | ... EV15: ='Sample Conc Calc'!FY608 -> #DIV/0!
A16: ='Analyte List'!A185 -> 3-Br-Phe | B16: ='Analyte List'!K185 -> 0 | C16: ='Sample Conc Calc'!AF609 -> #DIV/0! | D16: ='Sample Conc Calc'!AG609 -> #DIV/0! | E16: ='Sample Conc Calc'!AH609 -> #DIV/0! | F16: ='Sample Conc Calc'!AI609 -> #DIV/0! | G16: ='Sample Conc Calc'!AJ609 -> #DIV/0! | H16: ='Sample Conc Calc'!AK609 -> #DIV/0! | I16: ='Sample Conc Calc'!AL609 -> #DIV/0! | J16: ='Sample Conc Calc'!AM609 -> #DIV/0! | ... EV16: ='Sample Conc Calc'!FY609 -> #DIV/0!
A17: ='Analyte List'!A186 -> 1-Br-Ant | B17: ='Analyte List'!K186 -> 0 | C17: ='Sample Conc Calc'!AF610 -> #DIV/0! | D17: ='Sample Conc Calc'!AG610 -> #DIV/0! | E17: ='Sample Conc Calc'!AH610 -> #DIV/0! | F17: ='Sample Conc Calc'!AI610 -> #DIV/0! | G17: ='Sample Conc Calc'!AJ610 -> #DIV/0! | H17: ='Sample Conc Calc'!AK610 -> #DIV/0! | I17: ='Sample Conc Calc'!AL610 -> #DIV/0! | J17: ='Sample Conc Calc'!AM610 -> #DIV/0! | ... EV17: ='Sample Conc Calc'!FY610 -> #DIV/0!
A18: ='Analyte List'!A187 -> 1,4-Cl2-Ant | B18: ='Analyte List'!K187 -> 0 | C18: ='Sample Conc Calc'!AF611 -> #DIV/0! | D18: ='Sample Conc Calc'!AG611 -> #DIV/0! | E18: ='Sample Conc Calc'!AH611 -> #DIV/0! | F18: ='Sample Conc Calc'!AI611 -> #DIV/0! | G18: ='Sample Conc Calc'!AJ611 -> #DIV/0! | H18: ='Sample Conc Calc'!AK611 -> #DIV/0! | I18: ='Sample Conc Calc'!AL611 -> #DIV/0! | J18: ='Sample Conc Calc'!AM611 -> #DIV/0! | ... EV18: ='Sample Conc Calc'!FY611 -> #DIV/0!
A19: ='Analyte List'!A188 -> 1,5-Cl2-Ant | B19: ='Analyte List'!K188 -> 0 | C19: ='Sample Conc Calc'!AF612 -> #DIV/0! | D19: ='Sample Conc Calc'!AG612 -> #DIV/0! | E19: ='Sample Conc Calc'!AH612 -> #DIV/0! | F19: ='Sample Conc Calc'!AI612 -> #DIV/0! | G19: ='Sample Conc Calc'!AJ612 -> #DIV/0! | H19: ='Sample Conc Calc'!AK612 -> #DIV/0! | I19: ='Sample Conc Calc'!AL612 -> #DIV/0! | J19: ='Sample Conc Calc'!AM612 -> #DIV/0! | ... EV19: ='Sample Conc Calc'!FY612 -> #DIV/0!
... A30: ='Analyte List'!A199 -> 2,3,9,10-Br4-Ant | B30: ='Analyte List'!K199 -> 0 | C30: ='Sample Conc Calc'!AF623 -> #VALUE! | D30: ='Sample Conc Calc'!AG623 -> #VALUE! | E30: ='Sample Conc Calc'!AH623 -> #VALUE! | F30: ='Sample Conc Calc'!AI623 -> #VALUE! | G30: ='Sample Conc Calc'!AJ623 -> #VALUE! | H30: ='Sample Conc Calc'!AK623 -> #VALUE! | I30: ='Sample Conc Calc'!AL623 -> #VALUE! | J30: ='Sample Conc Calc'!AM623 -> #VALUE! | ... EV30: ='Sample Conc Calc'!FY623 -> #DIV/0!

Sheet Test Report Review
A1: Test Report Review
A2: ='Cover Page'!B3 -> Report Number | B2: ='Cover Page'!C3 -> 0
A4: Test Report Review tab is for INTERNAL USE ONLY
A6: GENERAL REQUIREMENTS (commonly listed as per SOP-023 Test Reports) | B6: Y/N | C6: REVIEWER | D6: DATE
A8: Report title (Test Report – Project name/description)
A9: Test Report Revision#
A10: Name and address of the laboratory
A11: Location of performance of the laboratory activities
A12: Identification of the person(s) preparing, reviewing and authorizing the report
A13: Name and contact information of the customer
A14: Identification of the test method used
A15: Date(s) of performance of the laboratory activities
A16: Date of issue of the report
A17: Unambiguous identification of the test item(s)
A18: Results with the units of measurement including reporting limits (if applicable)
A20: REQUIREMENTS (not commonly listed as per SOP-023 Test Reports) | B20: Y/N | C20: REVIEWER | D20: DATE
A22: List requirement(s)(if applicable)
A24: GENERAL QC REQUIREMENTS (see QC section of TM for specific P/F requirements) | B24: P/F | C24: REVIEWER | D24: DATE | E24: DEVIATION | F24: RISK ASSESSMENT | G24: COMMENTS | H24: AUTHORIZATION | I24: DATE
A26: Reagent/Method blank(s)
A27: Calibration
A28: RIS Recoveries
A29: Positive Control (SRM or other suitable/identified positive control sample)
A30: Duplicate Repeatability (if applicable)
A31: Control Chart Verification (Y/N)
A32: Other (list requirement)(if applicable)
A34: REVIEW OF REPORTED RESULTS | B34: Y/N | C34: REVIEWER | D34: DATE
A36: Visual inspection of 'Report Sheet' for sample outliers
A37: Visual comparison of results to previously reported results of similar test items (if applicable)
A38: Other (list and describe)(if applicable)

Sheet Sample Set Info
A1: Sample Set Information
A3: Report Number: | B3: ='Cover Page'!C3 -> 0
A4: Test Method: | B4: ='Cover Page'!C15 -> 0
A5: Instrument: | B5: Agilent GC-MSMS - COGRAD-XXX
A6: Acquisition Method File:
A7: Sample Set File:
A8: Acquisition Date:
A9: Data Processing Method File:
A11: Sample Reference Codes
A13: COGRAD Sample ID | B13: Client Sample ID | C13: Sample Mass or Volume | D13: Vf (Final Extract Volume) | E13: % Lipid Content (if applicable) | F13: Multiplier | G13: Divisor | H13: Correction Factor
C14: (add units) | D14: (add units)
A16: Mth Blk-1 | B16: n/a | C16: n/a | D16: 200 | E16: n/a | F16: 1 | G16: 1 | H16: =F16/G16 -> 1
A17: Mth Blk-2 | B17: n/a | C17: n/a | E17: n/a | F17: 1 | G17: 1 | H17: =F17/G17 -> 1
A18: Mth Blk-3 | B18: n/a | C18: n/a | E18: n/a | F18: 1 | G18: 1 | H18: =F18/G18 -> 1
A19: Mth Blk-4 | B19: n/a | C19: n/a | E19: n/a | F19: 1 | G19: 1 | H19: =F19/G19 -> 1
A20: CS Blank-1 | F20: 1 | G20: 1 | H20: =F20/G20 -> 1
A21: CS Blank-2 | F21: 1 | G21: 1 | H21: =F21/G21 -> 1
A22: CS Blank-3 | F22: 1 | G22: 1 | H22: =F22/G22 -> 1
A23: CS Blank-4 | F23: 1 | G23: 1 | H23: =F23/G23 -> 1
A24: CS Spike-1 | F24: 1 | G24: 1 | H24: =F24/G24 -> 1
A25: CS Spike-2 | F25: 1 | G25: 1 | H25: =F25/G25 -> 1
A26: CS Spike-3 | F26: 1 | G26: 1 | H26: =F26/G26 -> 1
A27: CS Spike-4 | F27: 1 | G27: 1 | H27: =F27/G27 -> 1
A28: CRM-1 | F28: 1 | G28: 1 | H28: =F28/G28 -> 1
A29: CRM-2 | F29: 1 | G29: 1 | H29: =F29/G29 -> 1
A30: CRM-3 | F30: 1 | G30: 1 | H30: =F30/G30 -> 1
A31: CRM-4 | F31: 1 | G31: 1 | H31: =F31/G31 -> 1
... A181: S150 | F181: 1 | G181: 1 | H181: =F181/G181 -> 1

Sheet Analyte List
A1: Analyte Peak List (SORTED); Internal Standard Dependencies; Calibration Standard Info (Prep date and Calibration Concentrations); Limits of Detection (LODs)
A3: ='Cover Page'!B3 -> Report Number | B3: ='Cover Page'!C3 -> 0
E5: Calibration Standards | G5: Calibration Standard Concentration (pg/uL) | K5: LOD
A6: Group/Peak ID by RRT | B6: Abbreviation | C6: ISTD ID | D6: ISTD Dependency | E6: Cali Std ID | F6: Prep Date | G6: LOW | H6: MED | I6: HIGH | K6: (add units)
A7: PAHs | B7: PAHs | K7: copy/paste from LOD spreadsheet
A9: Napthalene | B9: ='Raw Data-Unsorted'!A9 -> Nap | C9: n/a | D9: 2 | E9: PAH/APAH | G9: 10 | H9: 100 | I9: 1000
A10: Acenapthylene | B10: ='Raw Data-Unsorted'!A27 -> Acy | C10: n/a | D10: 3 | E10: PAH/APAH | G10: 10 | H10: 100 | I10: 1000
A11: Acenaphthene | B11: ='Raw Data-Unsorted'!A30 -> Ace | C11: n/a | D11: 4 | E11: PAH/APAH | G11: 10 | H11: 100 | I11: 1000
A12: Fluorene | B12: ='Raw Data-Unsorted'!A41 -> Flu | C12: n/a | D12: 5 | E12: PAH/APAH | G12: 10 | H12: 100 | I12: 1000
A13: Phenanthrene | B13: ='Raw Data-Unsorted'!A64 -> Phe | C13: n/a | D13: 6 | E13: PAH/APAH | G13: 10 | H13: 100 | I13: 1000
A14: Anthracene | B14: ='Raw Data-Unsorted'!A67 -> Ant | C14: n/a | D14: 6 | E14: PAH/APAH | G14: 10 | H14: 100 | I14: 1000
A15: Fluoranthene | B15: ='Raw Data-Unsorted'!A112 -> Flt | C15: n/a | D15: 7 | E15: PAH/APAH | G15: 10 | H15: 100 | I15: 1000
A16: Pyrene | B16: ='Raw Data-Unsorted'!A118 -> Pyr | C16: n/a | D16: 8 | E16: PAH/APAH | G16: 10 | H16: 100 | I16: 1000
A17: Benz(a)anthracene | B17: ='Raw Data-Unsorted'!A159 -> BaA | C17: n/a | D17: 9 | E17: PAH/APAH | G17: 10 | H17: 100 | I17: 1000
